2018-07-04 17:36:53,403 - __main__ - INFO - 
Test initiated at: 2018-07-04 17:36

2018-07-04 18:07:33,054 - __main__ - INFO - 
Test initiated at: 2018-07-04 18:07

2018-07-04 18:07:43,998 - __main__ - INFO - 	using fee_m1 mirror

2018-07-04 18:07:53,312 - functions - INFO - 	1530752873.2330 checking if fee_m1 axes are coupled

2018-07-04 18:07:53,315 - functions - INFO - yGantry status: coupled
2018-07-04 18:07:53,316 - functions - INFO -  ygantry status: coupled
2018-07-04 18:08:25,421 - functions - INFO - 1530752905.3629 getting gantry differences for mirror fee_m1
2018-07-04 18:08:25,423 - functions - INFO - xgantry difference: -0.0027
2018-07-04 18:08:25,425 - functions - INFO - ygantry_difference: -0.0027
2018-07-04 18:10:56,799 - __main__ - INFO - 
Test initiated at: 2018-07-04 18:10

2018-07-04 18:11:06,692 - __main__ - INFO - 	using fee_m1 mirror

2018-07-04 18:11:37,649 - functions - INFO - checking if fee_m1 axes are coupled
2018-07-04 18:11:37,652 - functions - INFO - yGantry status: coupled
2018-07-04 18:11:37,653 - functions - INFO -  ygantry status: coupled
2018-07-04 18:11:43,553 - functions - INFO - getting gantry differences for mirror fee_m1
2018-07-04 18:11:43,556 - functions - INFO - xgantry difference: -0.0026
2018-07-04 18:11:43,559 - functions - INFO - ygantry_difference: -0.0026
2018-07-04 18:11:50,659 - functions - INFO - movement check....
2018-07-04 18:11:50,660 - functions - INFO - moving by 0.500000...
2018-07-04 18:25:17,945 - __main__ - INFO - 
Test initiated at: 2018-07-04 18:25

2018-07-04 18:25:25,297 - __main__ - INFO - 	using fee_m1 mirror
2018-07-04 18:25:31,437 - functions - INFO - checking if fee_m1 axes are coupled
2018-07-04 18:25:31,440 - functions - INFO - yGantry status: coupled
2018-07-04 18:25:31,442 - functions - INFO -  ygantry status: coupled
2018-07-04 18:25:32,586 - functions - INFO - getting gantry differences for mirror fee_m1
2018-07-04 18:25:32,588 - functions - INFO - xgantry difference: -0.0027
2018-07-04 18:25:32,589 - functions - INFO - ygantry_difference: -0.0027
2018-07-04 18:25:42,091 - functions - INFO - movement check....
2018-07-04 18:25:42,092 - functions - INFO - moving by 0.500000...
2018-07-04 18:25:42,101 - __main__ - ERROR - exception occured
Traceback (most recent call last):
  File "<ipython-input-7-8e141ceda5e0>", line 3, in <module>
    test.w_timeout(test.gantry_checks(test_object.xgantry, 0.5), 300)
  File "/reg/neh/home5/gaire01/HOMS_tst/functions.py", line 41, in gantry_checks
    object_method.umvr(how_much)
  File "/reg/g/pcds/pyps/conda/py36/envs/pcds-1.2.0/lib/python3.6/site-packages/pcdsdevices/mv_interface.py", line 146, in umvr
    self.umv(delta + self.wm(), timeout=timeout)
  File "/reg/g/pcds/pyps/conda/py36/envs/pcds-1.2.0/lib/python3.6/site-packages/pcdsdevices/mv_interface.py", line 125, in umv
    status = self.move(position, timeout=timeout, wait=False)
  File "/reg/g/pcds/pyps/conda/py36/envs/pcds-1.2.0/lib/python3.6/site-packages/ophyd/pv_positioner.py", line 194, in move
    self._setup_move(position)
  File "/reg/g/pcds/pyps/conda/py36/envs/pcds-1.2.0/lib/python3.6/site-packages/ophyd/pv_positioner.py", line 148, in _setup_move
    self.setpoint.put(position, wait=True)
  File "/reg/g/pcds/pyps/conda/py36/envs/pcds-1.2.0/lib/python3.6/site-packages/ophyd/signal.py", line 899, in put
    self._write_pv.put(value, use_complete=use_complete, **kwargs)
  File "/reg/g/pcds/pyps/conda/py36/envs/pcds-1.2.0/lib/python3.6/site-packages/epics/pv.py", line 395, in put
    callback_data=callback_data)
  File "/reg/g/pcds/pyps/conda/py36/envs/pcds-1.2.0/lib/python3.6/site-packages/epics/ca.py", line 439, in wrapper
    return fcn(*args, **kwds)
  File "/reg/g/pcds/pyps/conda/py36/envs/pcds-1.2.0/lib/python3.6/site-packages/epics/ca.py", line 1453, in put
    PySEVCHK('put', ret)
  File "/reg/g/pcds/pyps/conda/py36/envs/pcds-1.2.0/lib/python3.6/site-packages/epics/ca.py", line 468, in PySEVCHK
    raise CASeverityException(func_name, message(status))
epics.ca.CASeverityException:  put returned 'Write access denied'
2018-07-04 18:29:28,902 - __main__ - ERROR - exception occured
Traceback (most recent call last):
  File "<ipython-input-8-fd686ce35e00>", line 2, in <module>
    test.w_timeout(test.request_change_verify_axis(test_object.ygantry, initial_ygantry_value, 0.5, 0.7), 300)
NameError: name 'initial_ygantry_value' is not defined
2018-07-04 18:29:38,757 - __main__ - INFO - 	1530754178.7362 recording original position...

2018-07-04 18:29:38,761 - __main__ - INFO - initial mirror angle is 242.0574 urad
2018-07-04 18:29:38,763 - __main__ - INFO - initial xgantry value is -0.7031 mm
2018-07-04 18:29:38,764 - __main__ - INFO - initial ygantry value is -0.0012 mm
2018-07-04 18:29:42,705 - functions - INFO - initial move...
2018-07-04 18:29:42,710 - __main__ - ERROR - exception occured
Traceback (most recent call last):
  File "<ipython-input-10-ef8077b8db54>", line 2, in <module>
    test.w_timeout(test.request_change_verify_axis(test_object.xgantry, initial_xgantry_value, 0.5, 0.7), 300)
  File "/reg/neh/home5/gaire01/HOMS_tst/functions.py", line 70, in request_change_verify_axis
    object_method.mv(initial_move_to)
  File "/reg/g/pcds/pyps/conda/py36/envs/pcds-1.2.0/lib/python3.6/site-packages/pcdsdevices/mv_interface.py", line 49, in mv
    self.move(position, timeout=timeout, wait=wait)
  File "/reg/g/pcds/pyps/conda/py36/envs/pcds-1.2.0/lib/python3.6/site-packages/ophyd/pv_positioner.py", line 194, in move
    self._setup_move(position)
  File "/reg/g/pcds/pyps/conda/py36/envs/pcds-1.2.0/lib/python3.6/site-packages/ophyd/pv_positioner.py", line 148, in _setup_move
    self.setpoint.put(position, wait=True)
  File "/reg/g/pcds/pyps/conda/py36/envs/pcds-1.2.0/lib/python3.6/site-packages/ophyd/signal.py", line 899, in put
    self._write_pv.put(value, use_complete=use_complete, **kwargs)
  File "/reg/g/pcds/pyps/conda/py36/envs/pcds-1.2.0/lib/python3.6/site-packages/epics/pv.py", line 395, in put
    callback_data=callback_data)
  File "/reg/g/pcds/pyps/conda/py36/envs/pcds-1.2.0/lib/python3.6/site-packages/epics/ca.py", line 439, in wrapper
    return fcn(*args, **kwds)
  File "/reg/g/pcds/pyps/conda/py36/envs/pcds-1.2.0/lib/python3.6/site-packages/epics/ca.py", line 1453, in put
    PySEVCHK('put', ret)
  File "/reg/g/pcds/pyps/conda/py36/envs/pcds-1.2.0/lib/python3.6/site-packages/epics/ca.py", line 468, in PySEVCHK
    raise CASeverityException(func_name, message(status))
epics.ca.CASeverityException:  put returned 'Write access denied'
